<?xml version="1.0" encoding="utf-8"?>
<!-- This URDF was created by Ben-ya Halevy (benyaiol1@gmail.com) with the help of the SolidWorks to URDF Exporter! Originally created by Stephen Brawner (brawner@gmail.com)
     Commit Version: 1.6.0-1-g15f4949  Build Version: 1.6.7594.29634
     For more information, please see http://wiki.ros.org/sw_urdf_exporter -->
<robot
  name="kitchen">
  <link
    name="base_link">
    <inertial>
      <origin
        xyz="0.078119 0.12635 0.43734"
        rpy="0 0 0" />
      <mass
        value="308.53" />
      <inertia
        ixx="153.43"
        ixy="-34.366"
        ixz="-3.9686"
        iyy="190.69"
        iyz="-15.336"
        izz="144.6" />
    </inertial>
    <visual>
      <origin
        xyz="0 0 0"
        rpy="0 0 0" />
      <geometry>
        <mesh
          filename="package://kitchen/meshes/base_link.STL" />
      </geometry>
      <material
        name="bright_grey">
        <color
          rgba="0.9 0.9 0.9 1" />
      </material>
    </visual>
    <collision concave="yes">
      <origin
        xyz="0 0 0"
        rpy="0 0 0" />
      <geometry>
        <mesh
          filename="package://kitchen/meshes/base_link.STL" />
      </geometry>
    </collision>
  </link>
  <link
    name="hot_plate">
    <inertial>
      <origin
        xyz="0.25 0.0087343 0.25"
        rpy="0 0 0" />
      <mass
        value="5.6431" />
      <inertia
        ixx="0.086722"
        ixy="2.8333E-17"
        ixz="1.0151E-17"
        iyy="0.17241"
        iyz="-2.1474E-17"
        izz="0.086722" />
    </inertial>
    <visual>
      <origin
        xyz="0 0 0"
        rpy="0 0 0" />
      <geometry>
        <mesh
          filename="package://kitchen/meshes/hot_plate.STL" />
      </geometry>
      <material
        name="black">
        <color
          rgba="0.3 0.3 0.3 1" />
      </material>
    </visual>
    <collision>
      <origin
        xyz="0 0 0"
        rpy="0 0 0" />
      <geometry>
        <mesh
          filename="package://kitchen/meshes/hot_plate.STL" />
      </geometry>
    </collision>
  </link>
  <joint
    name="hot_plate_fixed"
    type="fixed">
    <origin
      xyz="0.096699 0.48639 0.68"
      rpy="-1.5708 0 -1.5708" />
    <parent
      link="base_link" />
    <child
      link="hot_plate" />
    <axis
      xyz="0 0 0" />
  </joint>
  <link
    name="sink">
    <inertial>
      <origin
        xyz="-0.11955 0.44222 0.053"
        rpy="0 0 0" />
      <mass
        value="7.7349" />
      <inertia
        ixx="0.13549"
        ixy="-0.0016799"
        ixz="0.00016371"
        iyy="0.23449"
        iyz="0.0015904"
        izz="0.13577" />
    </inertial>
    <visual>
      <origin
        xyz="0 0 0"
        rpy="0 0 0" />
      <geometry>
        <mesh
          filename="package://kitchen/meshes/sink.STL" />
      </geometry>
      <material
        name="white">
        <color
          rgba="1 1 1 1" />
      </material>
    </visual>
    <collision concave="yes">
      <origin
        xyz="0 0 0"
        rpy="0 0 0" />
      <geometry>
        <mesh
          filename="package://kitchen/meshes/sink.STL" />
      </geometry>
    </collision>
  </link>
  <joint
    name="sink_fixed"
    type="fixed">
    <origin
      xyz="0.97831 0.37821 0.18277"
      rpy="1.5708 0 0.4277" />
    <parent
      link="base_link" />
    <child
      link="sink" />
    <axis
      xyz="0 0 0" />
  </joint>
  <link
    name="shelves">
    <inertial>
      <origin
        xyz="0.15 -2.2204E-16 1.1102E-16"
        rpy="0 0 0" />
      <mass
        value="33.12" />
      <inertia
        ixx="5.2606"
        ixy="-1.2468E-18"
        ixz="7.9797E-17"
        iyy="5.5045"
        iyz="1.8489E-32"
        izz="0.25282" />
    </inertial>
    <visual>
      <origin
        xyz="0 0 0"
        rpy="0 0 0" />
      <geometry>
        <mesh
          filename="package://kitchen/meshes/shelves.STL" />
      </geometry>
      <material
        name="dark_brown">
        <color
          rgba="0.7 0.5 0.3 1" />
      </material>
    </visual>
    <collision concave="yes">
      <origin
        xyz="0 0 0"
        rpy="0 0 0" />
      <geometry>
        <mesh
          filename="package://kitchen/meshes/shelves.STL" />
      </geometry>
    </collision>
  </link>
  <joint
    name="shelves_fixed"
    type="fixed">
    <origin
      xyz="-0.54 -0.15 1.245"
      rpy="1.5708 0 0" />
    <parent
      link="base_link" />
    <child
      link="shelves" />
    <axis
      xyz="0 0 0" />
  </joint>
  <link
    name="counter_top">
    <inertial>
      <origin
        xyz="0.0043832 0.015 -0.039975"
        rpy="0 0 0" />
      <mass
        value="39.344" />
      <inertia
        ixx="5.8999"
        ixy="-5.6936E-18"
        ixz="2.8484"
        iyy="13.492"
        iyz="-8.1262E-18"
        izz="7.5977" />
    </inertial>
    <visual>
      <origin
        xyz="0 0 0"
        rpy="0 0 0" />
      <geometry>
        <mesh
          filename="package://kitchen/meshes/counter_top.STL" />
      </geometry>
      <material
        name="brown">
        <color
          rgba="0.8 0.6 0.4 1" />
      </material>
    </visual>
    <collision>
      <origin
        xyz="0 0 0"
        rpy="0 0 0" />
      <geometry>
        <mesh
          filename="package://kitchen/meshes/counter_top.STL" />
      </geometry>
    </collision>
  </link>
  <joint
    name="counter_top_fixed"
    type="fixed">
    <origin
      xyz="0.04 -0.04 0.65"
      rpy="1.5708 0 0" />
    <parent
      link="base_link" />
    <child
      link="counter_top" />
    <axis
      xyz="0 0 0" />
  </joint>
  <link
    name="bottom_doors_right">
    <inertial>
      <origin
        xyz="0.58632 0.30937 0.01"
        rpy="0 0 0" />
      <mass
        value="13.974" />
      <inertia
        ixx="0.26407"
        ixy="-3.6033E-18"
        ixz="-1.8031E-18"
        iyy="0.35092"
        iyz="-7.6551E-19"
        izz="0.61405" />
    </inertial>
    <visual>
      <origin
        xyz="0 0 0"
        rpy="0 0 0" />
      <geometry>
        <mesh
          filename="package://kitchen/meshes/bottom_doors_right.STL" />
      </geometry>
      <material
        name="black">
        <color
          rgba="0.3 0.3 0.3 1" />
      </material>
    </visual>
    <collision>
      <origin
        xyz="0 0 0"
        rpy="0 0 0" />
      <geometry>
        <mesh
          filename="package://kitchen/meshes/bottom_doors_right.STL" />
      </geometry>
    </collision>
  </link>
  <joint
    name="bottom_fixed_right"
    type="fixed">
    <origin
      xyz="0 0 0"
      rpy="1.5708 0 0" />
    <parent
      link="base_link" />
    <child
      link="bottom_doors_right" />
    <axis
      xyz="0 0 0" />
  </joint>
  <link
    name="bottom_handles_right">
    <inertial>
      <origin
        xyz="0.12348 -0.12424 0.022433"
        rpy="0 0 0" />
      <mass
        value="0.374" />
      <inertia
        ixx="2.9114E-05"
        ixy="5.0518E-19"
        ixz="-9.5192E-20"
        iyy="0.0052838"
        iyz="-4.7773E-21"
        izz="0.0052796" />
    </inertial>
    <visual>
      <origin
        xyz="0 0 0"
        rpy="0 0 0" />
      <geometry>
        <mesh
          filename="package://kitchen/meshes/bottom_handles_right.STL" />
      </geometry>
      <material
        name="handles">
        <color
          rgba="0.8 0.8 0.8 1" />
      </material>
    </visual>
    <collision concave="yes">
      <origin
        xyz="0 0 0"
        rpy="0 0 0" />
      <geometry>
        <mesh
          filename="package://kitchen/meshes/bottom_handles_right.STL" />
      </geometry>
    </collision>
  </link>
  <joint
    name="bottom_handles_right_fixed"
    type="fixed">
    <origin
      xyz="0.35452 0.6 0.02"
      rpy="0 0 0" />
    <parent
      link="bottom_doors_right" />
    <child
      link="bottom_handles_right" />
    <axis
      xyz="0 0 0" />
  </joint>
  <link
    name="bottom_door_left">
    <inertial>
      <origin
        xyz="0.01 5.5511E-17 2.7756E-17"
        rpy="0 0 0" />
      <mass
        value="5.1072" />
      <inertia
        ixx="0.25097"
        ixy="2.8351E-19"
        ixz="0"
        iyy="0.062928"
        iyz="3.8272E-19"
        izz="0.18838" />
    </inertial>
    <visual>
      <origin
        xyz="0 0 0"
        rpy="0 0 0" />
      <geometry>
        <mesh
          filename="package://kitchen/meshes/bottom_door_left.STL" />
      </geometry>
      <material
        name="black">
        <color
          rgba="0.3 0.3 0.3 1" />
      </material>
    </visual>
    <collision>
      <origin
        xyz="0 0 0"
        rpy="0 0 0" />
      <geometry>
        <mesh
          filename="package://kitchen/meshes/bottom_door_left.STL" />
      </geometry>
    </collision>
  </link>
  <joint
    name="bottom_left_fixed"
    type="fixed">
    <origin
      xyz="0 -0.242 0.3125"
      rpy="1.5708 0 0" />
    <parent
      link="base_link" />
    <child
      link="bottom_door_left" />
    <axis
      xyz="0 0 0" />
  </joint>
  <link
    name="bottom_handle_left">
    <inertial>
      <origin
        xyz="0.021757 0 2.7756E-17"
        rpy="0 0 0" />
      <mass
        value="0.074" />
      <inertia
        ixx="0.00058588"
        ixy="8.9425E-23"
        ixz="1.0977E-20"
        iyy="0.00058725"
        iyz="-3.7873E-38"
        izz="6.305E-06" />
    </inertial>
    <visual>
      <origin
        xyz="0 0 0"
        rpy="0 0 0" />
      <geometry>
        <mesh
          filename="package://kitchen/meshes/bottom_handle_left.STL" />
      </geometry>
      <material
        name="handles">
        <color
          rgba="0.8 0.8 0.8 1" />
      </material>
    </visual>
    <collision concave="yes">
      <origin
        xyz="0 0 0"
        rpy="0 0 0" />
      <geometry>
        <mesh
          filename="package://kitchen/meshes/bottom_handle_left.STL" />
      </geometry>
    </collision>
  </link>
  <joint
    name="bottom_handle_left_fixed"
    type="fixed">
    <origin
      xyz="0.02 0.2825 0"
      rpy="0 0 0" />
    <parent
      link="bottom_door_left" />
    <child
      link="bottom_handle_left" />
    <axis
      xyz="0 0 0" />
  </joint>
  <link
    name="bottom_door">
    <inertial>
      <origin
        xyz="0.01 -0.3325 0.192"
        rpy="0 0 0" />
      <mass
        value="5.1072" />
      <inertia
        ixx="0.25097"
        ixy="-2.8351E-19"
        ixz="-1.5021E-19"
        iyy="0.062928"
        iyz="1.1272E-18"
        izz="0.18838" />
    </inertial>
    <visual>
      <origin
        xyz="0 0 0"
        rpy="0 0 0" />
      <geometry>
        <mesh
          filename="package://kitchen/meshes/bottom_door.STL" />
      </geometry>
      <material
        name="black">
        <color
          rgba="0.3 0.3 0.3 1" />
      </material>
    </visual>
    <collision concave="yes">
      <origin
        xyz="0 0 0"
        rpy="0 0 0" />
      <geometry>
        <mesh
          filename="package://kitchen/meshes/bottom_door.STL" />
      </geometry>
    </collision>
  </link>
  <joint
    name="bottom_hinge"
    type="revolute">
    <origin
      xyz="0 -0.82 -0.02"
      rpy="-1.5708 0 0" />
    <parent
      link="base_link" />
    <child
      link="bottom_door" />
    <axis
      xyz="0 -1 0" />
    <limit
      lower="-1.5708"
      upper="0"
      effort="0"
      velocity="0" />
  </joint>
  <link
    name="bottom_handle">
    <inertial>
      <origin
        xyz="0.021757 -1.1102E-16 0"
        rpy="0 0 0" />
      <mass
        value="0.074" />
      <inertia
        ixx="0.00058588"
        ixy="0"
        ixz="1.423E-20"
        iyy="0.00058725"
        iyz="-2.068E-22"
        izz="6.305E-06" />
    </inertial>
    <visual>
      <origin
        xyz="0 0 0"
        rpy="0 0 0" />
      <geometry>
        <mesh
          filename="package://kitchen/meshes/bottom_handle.STL" />
      </geometry>
      <material
        name="handles">
        <color
          rgba="0.8 0.8 0.8 1" />
      </material>
    </visual>
    <collision concave="yes">
      <origin
        xyz="0 0 0"
        rpy="0 0 0" />
      <geometry>
        <mesh
          filename="package://kitchen/meshes/bottom_handle.STL" />
      </geometry>
    </collision>
  </link>
  <joint
    name="bottom_fixed"
    type="fixed">
    <origin
      xyz="0.02 -0.615 0.192"
      rpy="3.1416 0 0" />
    <parent
      link="bottom_door" />
    <child
      link="bottom_handle" />
    <axis
      xyz="0 0 0" />
  </joint>
  <link
    name="sliding_door">
    <inertial>
      <origin
        xyz="-0.145 0.2 0.01"
        rpy="0 0 0" />
      <mass
        value="2.32" />
      <inertia
        ixx="0.031011"
        ixy="9.2519E-18"
        ixz="-1.1634E-19"
        iyy="0.016337"
        iyz="-4.7307E-21"
        izz="0.047193" />
    </inertial>
    <visual>
      <origin
        xyz="0 0 0"
        rpy="0 0 0" />
      <geometry>
        <mesh
          filename="package://kitchen/meshes/sliding_door.STL" />
      </geometry>
      <material
        name="black">
        <color
          rgba="0.3 0.3 0.3 1" />
      </material>
    </visual>
    <collision concave="yes">
      <origin
        xyz="0 0 0"
        rpy="0 0 0" />
      <geometry>
        <mesh
          filename="package://kitchen/meshes/sliding_door.STL" />
      </geometry>
    </collision>
  </link>
  <joint
    name="slider"
    type="prismatic">
    <origin
      xyz="0.81 0.19 1.15"
      rpy="1.5708 0 0" />
    <parent
      link="base_link" />
    <child
      link="sliding_door" />
    <axis
      xyz="1 0 0" />
    <limit
      lower="0"
      upper="0.3"
      effort="0"
      velocity="0" />
  </joint>
  <link
    name="sliding_handle">
    <inertial>
      <origin
        xyz="0 0 0.021842"
        rpy="0 0 0" />
      <mass
        value="0.038" />
      <inertia
        ixx="0.000384"
        ixy="-2.5439E-23"
        ixz="7.4749E-23"
        iyy="2.2544E-06"
        iyz="5.0397E-21"
        izz="0.00038238" />
    </inertial>
    <visual>
      <origin
        xyz="0 0 0"
        rpy="0 0 0" />
      <geometry>
        <mesh
          filename="package://kitchen/meshes/sliding_handle.STL" />
      </geometry>
      <material
        name="handles">
        <color
          rgba="0.8 0.8 0.8 1" />
      </material>
    </visual>
    <collision concave="yes">
      <origin
        xyz="0 0 0"
        rpy="0 0 0" />
      <geometry>
        <mesh
          filename="package://kitchen/meshes/sliding_handle.STL" />
      </geometry>
    </collision>
  </link>
  <joint
    name="sliding_fixed"
    type="fixed">
    <origin
      xyz="-0.265 0.2 0.02"
      rpy="0 0 0" />
    <parent
      link="sliding_door" />
    <child
      link="sliding_handle" />
    <axis
      xyz="0 0 0" />
  </joint>
  <link
    name="upper_right">
    <inertial>
      <origin
        xyz="-0.1405 0.2 0.01"
        rpy="0 0 0" />
      <mass
        value="2.248" />
      <inertia
        ixx="0.030048"
        ixy="-1.8504E-17"
        ixz="-8.2604E-20"
        iyy="0.014867"
        iyz="5.4117E-19"
        izz="0.044765" />
    </inertial>
    <visual>
      <origin
        xyz="0 0 0"
        rpy="0 0 0" />
      <geometry>
        <mesh
          filename="package://kitchen/meshes/upper_right.STL" />
      </geometry>
      <material
        name="black">
        <color
          rgba="0.3 0.3 0.3 1" />
      </material>
    </visual>
    <collision concave="yes">
      <origin
        xyz="0 0 0"
        rpy="0 0 0" />
      <geometry>
        <mesh
          filename="package://kitchen/meshes/upper_right.STL" />
      </geometry>
    </collision>
  </link>
  <joint
    name="upper_right_hinge"
    type="revolute">
    <origin
      xyz="0.495 0.19 1.15"
      rpy="1.5708 0 0" />
    <parent
      link="base_link" />
    <child
      link="upper_right" />
    <axis
      xyz="0 -1 0" />
    <limit
      lower="-1.5708"
      upper="0"
      effort="0"
      velocity="0" />
  </joint>
  <link
    name="right_handle">
    <inertial>
      <origin
        xyz="-2.7756E-17 2.2204E-16 0.021842"
        rpy="0 0 0" />
      <mass
        value="0.038" />
      <inertia
        ixx="0.000384"
        ixy="-2.5439E-23"
        ixz="5.4333E-23"
        iyy="2.2544E-06"
        iyz="7.1219E-21"
        izz="0.00038238" />
    </inertial>
    <visual>
      <origin
        xyz="0 0 0"
        rpy="0 0 0" />
      <geometry>
        <mesh
          filename="package://kitchen/meshes/right_handle.STL" />
      </geometry>
      <material
        name="handles">
        <color
          rgba="0.8 0.8 0.8 1" />
      </material>
    </visual>
    <collision concave="yes">
      <origin
        xyz="0 0 0"
        rpy="0 0 0" />
      <geometry>
        <mesh
          filename="package://kitchen/meshes/right_handle.STL" />
      </geometry>
    </collision>
  </link>
  <joint
    name="right_fixed"
    type="fixed">
    <origin
      xyz="-0.256 0.2 0.02"
      rpy="0 0 0" />
    <parent
      link="upper_right" />
    <child
      link="right_handle" />
    <axis
      xyz="0 0 0" />
  </joint>
  <link
    name="upper_left">
    <inertial>
      <origin
        xyz="0.1405 -0.2 -0.01"
        rpy="0 0 0" />
      <mass
        value="2.248" />
      <inertia
        ixx="0.030048"
        ixy="7.9272E-18"
        ixz="-1.0079E-19"
        iyy="0.014867"
        iyz="-1.4015E-18"
        izz="0.044765" />
    </inertial>
    <visual>
      <origin
        xyz="0 0 0"
        rpy="0 0 0" />
      <geometry>
        <mesh
          filename="package://kitchen/meshes/upper_left.STL" />
      </geometry>
      <material
        name="black">
        <color
          rgba="0.3 0.3 0.3 1" />
      </material>
    </visual>
    <collision concave="yes">
      <origin
        xyz="0 0 0"
        rpy="0 0 0" />
      <geometry>
        <mesh
          filename="package://kitchen/meshes/upper_left.STL" />
      </geometry>
    </collision>
  </link>
  <joint
    name="left_hinge"
    type="revolute">
    <origin
      xyz="-0.07 0.19 1.15"
      rpy="-1.5708 0 0" />
    <parent
      link="base_link" />
    <child
      link="upper_left" />
    <axis
      xyz="0 -1 0" />
    <limit
      lower="-1.5708"
      upper="0"
      effort="0"
      velocity="0" />
  </joint>
  <link
    name="left_handle">
    <inertial>
      <origin
        xyz="0 2.2204E-16 0.021842"
        rpy="0 0 0" />
      <mass
        value="0.038" />
      <inertia
        ixx="0.000384"
        ixy="7.2076E-21"
        ixz="-1.2807E-22"
        iyy="2.2544E-06"
        iyz="2.0723E-21"
        izz="0.00038238" />
    </inertial>
    <visual>
      <origin
        xyz="0 0 0"
        rpy="0 0 0" />
      <geometry>
        <mesh
          filename="package://kitchen/meshes/left_handle.STL" />
      </geometry>
      <material
        name="handles">
        <color
          rgba="0.8 0.8 0.8 1" />
      </material>
    </visual>
    <collision concave="yes">
      <origin
        xyz="0 0 0"
        rpy="0 0 0" />
      <geometry>
        <mesh
          filename="package://kitchen/meshes/left_handle.STL" />
      </geometry>
    </collision>
  </link>
  <joint
    name="left_fixed"
    type="fixed">
    <origin
      xyz="0.256 -0.2 -0.02"
      rpy="3.1416 0 3.1416" />
    <parent
      link="upper_left" />
    <child
      link="left_handle" />
    <axis
      xyz="0 0 0" />
  </joint>
  <link
    name="control_box">
    <inertial>
      <origin
        xyz="5.5511E-17 2.2204E-16 0.099975"
        rpy="0 0 0" />
      <mass
        value="23.992" />
      <inertia
        ixx="0.1599"
        ixy="6.28E-17"
        ixz="1.419E-17"
        iyy="0.79957"
        iyz="1.1985E-17"
        izz="0.7996" />
    </inertial>
    <visual>
      <origin
        xyz="0 0 0"
        rpy="0 0 0" />
      <geometry>
        <mesh
          filename="package://kitchen/meshes/control_box.STL" />
      </geometry>
      <material
        name="black">
        <color
          rgba="0.3 0.3 0.3 1" />
      </material>
    </visual>
    <collision concave="yes">
      <origin
        xyz="0 0 0"
        rpy="0 0 0" />
      <geometry>
        <mesh
          filename="package://kitchen/meshes/control_box.STL" />
      </geometry>
    </collision>
  </link>
  <joint
    name="box_fixed"
    type="fixed">
    <origin
      xyz="0.34 0.54 1.05"
      rpy="1.5708 0 0" />
    <parent
      link="base_link" />
    <child
      link="control_box" />
    <axis
      xyz="0 0 0" />
  </joint>
  <link
    name="control_knob_1">
    <inertial>
      <origin
        xyz="-6.6991E-09 0.00060519 0.007192"
        rpy="0 0 0" />
      <mass
        value="0.048661" />
      <inertia
        ixx="1.7794E-05"
        ixy="-9.3952E-12"
        ixz="1.3861E-12"
        iyy="1.2594E-05"
        iyz="-2.3176E-07"
        izz="2.7874E-05" />
    </inertial>
    <visual>
      <origin
        xyz="0 0 0"
        rpy="0 0 0" />
      <geometry>
        <mesh
          filename="package://kitchen/meshes/control_knob_1.STL" />
      </geometry>
      <material
        name="">
        <color
          rgba="0.49804 0.49804 0.49804 1" />
      </material>
    </visual>
    <collision concave="yes">
      <origin
        xyz="0 0 0"
        rpy="0 0 0" />
      <geometry>
        <mesh
          filename="package://kitchen/meshes/control_knob_1.STL" />
      </geometry>
    </collision>
  </link>
  <joint
    name="knob_1"
    type="revolute">
    <origin
      xyz="-0.225 0 0.2"
      rpy="0 0 0" />
    <parent
      link="control_box" />
    <child
      link="control_knob_1" />
    <axis
      xyz="0 0 1" />
    <limit
      lower="0"
      upper="1.5708"
      effort="0"
      velocity="0" />
  </joint>
  <link
    name="control_knob_2">
    <inertial>
      <origin
        xyz="-6.6991E-09 0.00060519 0.007192"
        rpy="0 0 0" />
      <mass
        value="0.048661" />
      <inertia
        ixx="1.7794E-05"
        ixy="-9.3952E-12"
        ixz="1.3861E-12"
        iyy="1.2594E-05"
        iyz="-2.3176E-07"
        izz="2.7874E-05" />
    </inertial>
    <visual>
      <origin
        xyz="0 0 0"
        rpy="0 0 0" />
      <geometry>
        <mesh
          filename="package://kitchen/meshes/control_knob_2.STL" />
      </geometry>
      <material
        name="">
        <color
          rgba="0.49804 0.49804 0.49804 1" />
      </material>
    </visual>
    <collision concave="yes">
      <origin
        xyz="0 0 0"
        rpy="0 0 0" />
      <geometry>
        <mesh
          filename="package://kitchen/meshes/control_knob_2.STL" />
      </geometry>
    </collision>
  </link>
  <joint
    name="knob_2"
    type="revolute">
    <origin
      xyz="-0.075 0 0.2"
      rpy="0 0 0" />
    <parent
      link="control_box" />
    <child
      link="control_knob_2" />
    <axis
      xyz="0 0 1" />
    <limit
      lower="0"
      upper="1.5708"
      effort="0"
      velocity="0" />
  </joint>
  <link
    name="control_knob_3">
    <inertial>
      <origin
        xyz="-6.6991E-09 0.00060519 0.007192"
        rpy="0 0 0" />
      <mass
        value="0.048661" />
      <inertia
        ixx="1.7794E-05"
        ixy="-9.3952E-12"
        ixz="1.3861E-12"
        iyy="1.2594E-05"
        iyz="-2.3176E-07"
        izz="2.7874E-05" />
    </inertial>
    <visual>
      <origin
        xyz="0 0 0"
        rpy="0 0 0" />
      <geometry>
        <mesh
          filename="package://kitchen/meshes/control_knob_3.STL" />
      </geometry>
      <material
        name="">
        <color
          rgba="0.49804 0.49804 0.49804 1" />
      </material>
    </visual>
    <collision concave="yes">
      <origin
        xyz="0 0 0"
        rpy="0 0 0" />
      <geometry>
        <mesh
          filename="package://kitchen/meshes/control_knob_3.STL" />
      </geometry>
    </collision>
  </link>
  <joint
    name="knob_3"
    type="revolute">
    <origin
      xyz="0.075 0 0.2"
      rpy="0 0 0" />
    <parent
      link="control_box" />
    <child
      link="control_knob_3" />
    <axis
      xyz="0 0 1" />
    <limit
      lower="0"
      upper="1.5708"
      effort="0"
      velocity="0" />
  </joint>
  <link
    name="control_knob_4">
    <inertial>
      <origin
        xyz="-6.6991E-09 0.00060519 0.007192"
        rpy="0 0 0" />
      <mass
        value="0.048661" />
      <inertia
        ixx="1.7794E-05"
        ixy="-9.3952E-12"
        ixz="1.3861E-12"
        iyy="1.2594E-05"
        iyz="-2.3176E-07"
        izz="2.7874E-05" />
    </inertial>
    <visual>
      <origin
        xyz="0 0 0"
        rpy="0 0 0" />
      <geometry>
        <mesh
          filename="package://kitchen/meshes/control_knob_4.STL" />
      </geometry>
      <material
        name="">
        <color
          rgba="0.49804 0.49804 0.49804 1" />
      </material>
    </visual>
    <collision concave="yes">
      <origin
        xyz="0 0 0"
        rpy="0 0 0" />
      <geometry>
        <mesh
          filename="package://kitchen/meshes/control_knob_4.STL" />
      </geometry>
    </collision>
  </link>
  <joint
    name="knob_4"
    type="revolute">
    <origin
      xyz="0.225 0 0.2"
      rpy="0 0 0" />
    <parent
      link="control_box" />
    <child
      link="control_knob_4" />
    <axis
      xyz="0 0 1" />
    <limit
      lower="0"
      upper="1.5708"
      effort="0"
      velocity="0" />
  </joint>
</robot>